Workbook

Sheet KALA T1
A1: UNIDADES VINCULADAS A FIDUCIARIA BANCOLOMBIA | J1: KALA TORRE 1
A2: VENTAS Y RECURSOS POR FIDEICOMISO
B3: GENERADO 22/06/2026
F6: Cartera de 6 a 30 dias (1) | O6: =O23 -> 2500000
F7: Cartera de 31 a 60 dias (2) | O7: =O40+O20 -> 24544162
F8: Cartera de 61 a 90 dias (1) | O8: =O17+O36 -> 6271268
F9: Cartera Mayor de 90 dias (3) | O9: =O13+O32 -> 23455024
A11: CARTERA EN GESTIÓN
A12: INVENTARIO | B12: INMUEBLE | C12: NOMENCLATURA | D12: AREA | E12: REFERENCIA | F12: PROPIETARIOS | G12: FECHA CONTRATO | H12: FECHA DE ENTREGA | I12: VALOR VENTA | J12: VALOR M2 | K12: VALOR ABONADO | L12: % RECAUDO | M12: CUOTAS MORA | N12: DIAS MORA | O12: VALOR VENCIDO | P12: OBSERVACIONES
F13: =F9 -> Cartera Mayor de 90 dias (3) | I13: =SUM(I14:I15) -> 1338211129 | K13: =SUM(K14:K15) -> 338303180 | O13: =SUM(O14:O15) -> 18936624
A14: Kala Golf | B14: 6-F | C14: 51606 | D14: 89.85 | E14: 1429615160607 | F14: _x000D_901380801 GRUPO LA CHIVA SAS (100.00%) | G14: 45412 | H14: 46367 | I14: 846341129 | J14: =I14/D14 -> 9419489.5 | K14: 214894066 | L14: =K14/I14 -> 0.25390952 | M14: 4 | N14: 101 | O14: 11420000 | P14: Cliente no responde las llamadas, se envio recordatorio de pago // CONTINUAR GESTION , se envia trecordatorio de pago junio 19 de 2026
A15: Kala Golf | B15: 5-C | C15: 51503 | D15: 48.7 | E15: 1603715150304 | F15: _x000D_1013601581 LAURA MARITZA RIOS BONILLA (25.00%) _x000D_51718689 ANA TULIA RIOS ROMERO (50.00%) _x000D_80229929 ARMANDO SILVA ROJAS (25.00%) | G15: 45316 | H15: 46266 | I15: 491870000 | J15: =I15/D15 -> 10100000 | K15: 123409114 | L15: =K15/I15 -> 0.25089783 | M15: 4 | N15: 108 | O15: 7516624 | P15: Compromiso de pago 02 de Junio 2026., NO CUMPLIO ; se continua la gestion
F17: =F8 -> Cartera de 61 a 90 dias (1) | I17: =I18+I19 -> 0 | K17: =K18+K19 -> 0 | O17: =O18+O19 -> 0
J18: =I18/D18 -> #DIV/0! | L18: =K18/I18 -> #DIV/0!
A19: Kala Golf | B19: 6-F | J19: =I19/D19 -> #DIV/0! | L19: =K19/I19 -> #DIV/0!
F20: =F7 -> Cartera de 31 a 60 dias (2) | I20: =I21 -> 996913848 | K20: =K21 -> 248547369 | O20: =O21 -> 21800000
A21: Kala Golf | B21: 1-A | C21: 51101 | D21: 114.44 | E21: 1429615110107 | F21: 5003788569 JULIA SKYE OLIVARES (50.00%) 79777577 ROBERTO CARLOS OLIVARES VILLA (50.00%) | G21: 44593 | H21: 46265 | I21: 996913848 | J21: =I21/D21 -> 8711236 | K21: 248547369 | L21: =K21/I21 -> 0.2493168 | M21: 2 | N21: 48 | O21: 21800000 | P21: Cliente no responde las llamadas, se continua gestion, se envio recordatorio con la informacion completa de su estado de cuenta , se solicita constestar nuetsros mensajes o contactarnos
J22: =I22/D22 -> #DIV/0! | L22: =K22/I22 -> #DIV/0!
F23: =F6 -> Cartera de 6 a 30 dias (1) | I23: =I24 -> 625121328 | K23: =K24 -> 142198808 | O23: =O24 -> 2500000
A24: Kala Golf | B24: 2-C | C24: 51203 | D24: 70.77 | E24: 1429615120300 | F24: _x000D_42151688 SILVANA DELGADO HOYOS (50.00%) _x000D_324809 LUIS ALEXANDRE MARTINS BRANCO (50.00%) | G24: 45348 | H24: 46295 | I24: 625121328 | J24: =I24/D24 -> 8833140.1 | K24: 142198808 | L24: =K24/I24 -> 0.22747393 | M24: 1 | N24: 18 | O24: 2500000 | P24: Cliente con compromiso de pago junio 10 de 2026
A25: Kala Golf | J25: =I25/D25 -> #DIV/0! | L25: =K25/I25 -> #DIV/0!
C26: =+COUNTA(C14:C25) -> 4 | F26: TOTALES | I26: =I13+I17+I23+I20 -> 2960246305 | K26: =K13+K17+K23+K20 -> 729049357 | O26: =O13+O17+O23+O20 -> 43236624
A30: CARTERA EN TRAMITE
A31: INVENTARIO | B31: INMUEBLE | C31: NOMENCLATURA | D31: AREA | E31: REFERENCIA | F31: PROPIETARIOS | G31: FECHA CONTRATO | H31: FECHA DE ENTREGA | I31: VALOR VENTA | J31: VALOR M2 | K31: VALOR ABONADO | L31: % RECAUDO | M31: CUOTAS MORA | N31: DIAS MORA | O31: VALOR VENCIDO | P31: OBSERVACIONES
F32: Cartera Mayor de 90 dias | I32: =I33 -> 684327316 | K32: =K33 -> 204000000 | O32: =O33 -> 4518400
A33: Kala Golf | B33: 2-O | C33: 51216 | D33: 110.8 | E33: 1429615121617 | F33: 42056572 MARIA MARLENNY PEREZ NARVAEZ | G33: 45581 | H33: 46294 | I33: 684327316 | J33: =I33/D33 -> 6176239.3 | K33: 204000000 | L33: 0.29810296 | M33: 5 | N33: 122 | O33: 4518400 | P33: Cliente informa pregunta sobre las fechas de entrega, por lo tento informa que no efectuara mas pagos, teniendo en cuenta que solo falta poco para cubrir el 30% de la CI.// EN ESPERA CONTACTO DE BRESCIA//, CLIENTE EN EXPERIENCIA PARA PACTAR FECHA DE ENTREGA
J34: =I34/D34 -> #DIV/0!
J35: =I35/D35 -> #DIV/0!
F36: Cartera de 61 a 90 dias | I36: =I37 -> 716700000 | K36: =K37 -> 204543952 | O36: =O37 -> 6271268
A37: Kala Golf | B37: 6-J | C37: 51610 | D37: 89.56 | E37: 1429615161003 | F37: _x000D_37723649 SANDRA ISABEL AYALA BLANCO (50.00%) _x000D_91490723 SERGIO FERNANDO RIOS (50.00%) | G37: 45354 | H37: 46305 | I37: 716700000 | J37: =I37/D37 -> 8002456.5 | K37: 204543952 | L37: =K37/I37 -> 0.28539689 | M37: 3 | N37: 68 | O37: 6271268 | P37: Cliente pdte por contactar por el area de experiencia al cliente.
J38: =I38/D38 -> #DIV/0!
J39: =I39/D39 -> #DIV/0!
F40: Cartera de 31 a 60 dias | I40: =I41+I42 -> 592718815 | J40: =I40/D40 -> #DIV/0! | K40: =K41+K42 -> 157571482 | O40: =O41+O42 -> 2744162
A41: Kala Golf | B41: 4-F | C41: 51406 | D41: 70.5 | E41: 1429615140605 | F41: _x000D_33480960 YELISA PALACIOS MARTINEZ (100.00%) | G41: 45399 | H41: 46259 | I41: 592718815 | J41: =I41/D41 -> 8407359.1 | K41: 157571482 | L41: =K41/I41 -> 0.26584525 | M41: 2 | N41: 40 | O41: 2744162 | P41: Cliente en el area de expriencia para su ajuste de fecha de entrega y ajuste de oportunidad en CRM
J42: =I42/D42 -> #DIV/0! | L42: =K42/I42 -> #DIV/0!
F43: Cartera de 6 a 30 dias | J43: =I43/D43 -> #DIV/0!
J44: =I44/D44 -> #DIV/0!
J45: =I45/D45 -> #DIV/0!
C46: =+COUNTA(C37:C45) -> 2 | F46: TOTALES | I46: =I40+I36+I40+I43 -> 1902137630 | K46: =K40+K36+K40+K43 -> 519686916 | O46: =O32+O36+O40 -> 13533830
F48: Total apartamentos torre | G48: 68
...

Sheet KALA T2 
C1: UNIDADES VINCULADAS A FIDUCIARIA BANCOLOMBIA | H1: KALA GOLF 2
C2: VENTAS Y RECURSOS POR FIDEICOMISO
D3: GENERADO 18/06/2026
D6: Cartera de 6 a 30 dias | M6: =M23 -> 5121300
D7: Catera de 31 a 60dias | M7: =M20 -> 52863178
D8: Cartera de 61 a 90 dias | M8: =M17+M37 -> 16245000
D9: Cartera Mayor de 90 dias | M9: =M13 -> 44878308
A11: CARTERA EN GESTIÓN
A12: NOMENCLATURA | B12: AREA | C12: REFERENCIA | D12: PROPIETARIOS | E12: FECHA CONTRATO | F12: FECHA DE ENTREGA | G12: VALOR VENTA | H12: VALOR M2 | I12: VALOR ABONADO | J12: % RECAUDO | K12: CUOTAS MORA | L12: DIAS MORA | M12: VALOR VENCIDO | N12: OBSERVACIONES
D13: =D9 -> Cartera Mayor de 90 dias | G13: =G14+G16+G15 -> 1961909368 | I13: =I14+I16+I15 -> 508350138 | M13: =M14+M16+M15 -> 44878308
A14: 4-H | B14: 80.92 | C14: 1429625240801 | D14: Mauricio Andrés Gaitán Cotes | E14: 45356 | F14: 46307 | G14: 730238296 | H14: =G14/B14 -> 9024200.4 | I14: 201771000 | J14: =I14/G14 -> 0.27630843 | K14: 6 | L14: 156 | M14: 12851400 | N14: Cliente realizo abono en junio de 3 mm, realiza pagos en el mes de valores bajos, se continua gestion de cartera (CI 7 CUOTAS 17.300.600)
A15: 5-N | B15: 82.44 | C15: 1429625251400 | D15: Giovanni Rodriguez Beltran | E15: 45398 | F15: 46356 | G15: 648013176 | H15: =G15/B15 -> 7860421.8 | I15: 170825950 | J15: =I15/G15 -> 0.26361493 | K15: 5 | L15: 138 | M15: 14105000 | N15: Cliente se envio notificacion el 26 de mayo, cliente continua realizando abonos en el mes enjunio pago $1MM (7 CI $23.578.400) Me comunique con la asesora comercial Laura Ortiz para que lo contactara y me ayudara con un arespuesta del valor adeudado, le escribe a la esposa en espera de confirmacion
A16: 2-I | B16: 80.92 | C16: 1429625220900 | D16: Magola Isabel Yepes Yepes | E16: 45377 | F16: 46294 | G16: 583657896 | H16: =G16/B16 -> 7212776.8 | I16: 135753188 | J16: =I16/G16 -> 0.23259034 | K16: 4 | L16: 109 | M16: 17921908 | N16: Cliente realiza compromiso para el 24 de junio $2.800.000 y el 26 de juni $4.000.000// se le informo que debia estar al dia con la mitad del de lo adeudado o se procederia a realizar desistimiento y me confirmo fecha 25 de junio//
D17: =D8 -> Cartera de 61 a 90 dias | G17: =G18+G19 -> 0 | I17: =I18+I19 -> 0 | M17: =M18+M19 -> 0
H18: =G18/B18 -> #DIV/0! | J18: =I18/G18 -> #DIV/0!
D20: =D7 -> Catera de 31 a 60dias | G20: =G21+G22 -> 1669005339 | I20: =I21+I22 -> 446952712 | M20: =+M21+M22 -> 52863178
A21: 2-A | B21: 111.21 | C21: 1603715220101 | D21: Narlis Blanco Hinestrosa | E21: 45847 | F21: 46527 | G21: 1118772600 | H21: =G21/B21 -> 10060000 | I21: 138452712 | J21: =I21/G21 -> 0.12375411 | K21: 2 | L21: 58 | M21: 32863178 | N21: Cliente informa pago para el dia 8 de julio Se envia recordatorio de pago, en espera de confirmacion de pago cliente generalmente paga una cuota se continua gestion
A22: 1-M | B22: 83.24 | C22: 1429625211305 | D22: Leidy Dayana Fernández Daza | E22: 45358 | F22: 46218 | G22: 550232739 | H22: =G22/B22 -> 6610196.3 | I22: 308500000 | J22: =I22/G22 -> 0.56067184 | K22: 2 | L22: 48 | M22: 20000000 | N22: Cliente realizo pago 1 cuota 10 mm se encuentra en porceso de palicacion estaban en partidas
D23: =D6 -> Cartera de 6 a 30 dias | G23: =G24+G25+G26+G27 -> 2591898285 | I23: =I24+I25+I26+I27 -> 756261395 | M23: =M24+M25+M26+M27 -> 5121300
A24: 2-D | B24: 75.31 | C24: 1429625220417 | D24: Ricardo Rodriguez Gonzalez | E24: 45152 | F24: 46433 | G24: 779000000 | H24: =G24/B24 -> 10343912 | I24: 229410473 | J24: =I24/G24 -> 0.29449355 | K24: 2 | L24: 38 | M24: 1072400 | N24: Cliente realizo pago despues de corte se encuentra al dia
A25: 6-H | B25: 89.36 | C25: 1429625260815 | D25: ANDRES LEONARDO DE LEON FERNANDEZ | E25: 45300 | G25: 673904522 | H25: =G25/B25 -> 7541456.2 | I25: 197486020 | J25: =I25/G25 -> 0.29304748 | K25: 1 | L25: 26 | M25: 1125600 | N25: Se envia recordatorio de pago
A26: 1-J | B26: 55.39 | C26: 1429625211002 | D26: LEIDY JOHANNA BARRERA NARVAEZ BRAGNNER ALEJANDRO VICUÑA BEJARANO | E26: 45399 | G26: 365365346 | H26: =G26/B26 -> 6596233 | I26: 100364902 | J26: =I26/G26 -> 0.27469738 | K26: 1 | L26: 23 | M26: 1466500 | N26: Se envia recordatorio de pago
A27: 4-O | B27: 110.8 | C27: 1429625241601 | D27: MARTIN JAVIER MARTINEZ LOZANO | E27: 45358 | G27: 773628417 | H27: =G27/B27 -> 6982205.9 | I27: 229000000 | J27: =I27/G27 -> 0.29600774 | K27: 1 | L27: 18 | M27: 1456800 | N27: Se envia recordatorio de pago
A28: =+COUNTA(A14:A27) -> 9 | D28: TOTALES | G28: =G13+G17+G20+G23 -> 6222812992 | I28: =I13+I17+I20+I23 -> 1711564245 | M28: =M13+M17+M20+M23 -> 102862786
A33: NOMENCLATURA | B33: AREA | C33: REFERENCIA | D33: PROPIETARIOS | E33: FECHA CONTRATO | F33: FECHA DE ENTREGA | G33: VALOR VENTA | H33: VALOR M2 | I33: VALOR ABONADO | J33: % RECAUDO | K33: CUOTAS MORA | L33: DIAS MORA | M33: VALOR VENCIDO | N33: OBSERVACIONES
D34: Cartera Mayor de 90 dias | G34: =G36 -> 862528502 | I34: =I36 -> 247850000 | M34: =M36 -> 11045600
A35: 4-J | B35: 48.59 | C35: 1429625241005 | D35: Ricardo Rivera | E35: 45356 | F35: 46258 | G35: 350925570 | H35: =G35/B35 -> 7222176.8 | I35: 86828000 | J35: =I35/G35 -> 0.24742569 | K35: 4 | L35: 101 | M35: 839554 | N35: Cliente pendiente firma de otrosi, saldo corresponde a valor total de CI
A36: 3-F | B36: 97.96 | C36: 1429625230608 | D36: MAURO Andres Farfan sarmiento | E36: 45503 | G36: 862528502 | H36: =G36/B36 -> 8804905.1 | I36: 247850000 | J36: =I36/G36 -> 0.28735282 | K36: 5 | L36: 143 | M36: 11045600 | N36: cliente tiene pendiente traslado de recursos del inmueble en TP1 525 se encuentra en proceso de autorizacion de GF
D37: Cartera de 61 a 90 dias | G37: =G38 -> 531752360 | I37: =I38 -> 117812705 | M37: =M38 -> 16245000
A38: 4-G | B38: 48.59 | C38: 1429625240700 | D38: ALEN JAVIER DIAZ PINZON | E38: 46007 | F38: 46374 | G38: 531752360 | H38: =G38/B38 -> 10943658 | I38: 117812705 | K38: 3 | L38: 61 | M38: 16245000 | N38: Cliente pendiente firma de otrosi
D39: Catera de 31 a 60dias | G39: =G40 -> 531973411 | I39: =I40 -> 156510000 | M39: =M40 -> 4785031
A40: 2-M | B40: 75.31 | C40: 1429625221318 | D40: Darío Yoany Mesa Ruiz | E40: 45759 | F40: 46234 | G40: 531973411 | H40: =G40/B40 -> 7063781.8 | I40: 156510000 | J40: =I40/G40 -> 0.29420643 | K40: 2 | L40: 48 | M40: 4785031 | N40: Cliente pendiente firma de otrosi
D42: Cartera de 6 a 30 dias | G42: =G43 -> 773628417 | I42: =I43 -> 229000000 | M42: =M43 -> 1456800
A43: 4-O | B43: 110.8 | C43: 1429625241601 | D43: MARTIN JAVIER MARTINEZ LOZANO | E43: 45358 | G43: 773628417 | H43: =G43/B43 -> 6982205.9 | I43: 229000000 | J43: =I43/G43 -> 0.29600774 | K43: 1 | L43: 18 | M43: 1456800 | N43: Cliente pendiente firma de otrosi
A44: =+COUNTA(A36:A43) -> 4 | D44: TOTALES | F44: =SUM(F38:F43) -> 92608 | G44: =G34+G42+G37+G39 -> 2699882690 | I44: =I34+I42+I37+I39 -> 751172705 | M44: =M34+M37+M39+M42 -> 33532431
D46: Total apartamentos torre | E46: 72
D47: Apartamentos en inventario | E47: =E46-E48 -> 5
D48: Numero de Clientes Vinculados | E48: =[3]KALA2!C70 -> 67
D49: Recaudo Mayo | E49: =[3]KALA2!L70 -> 71057486
D50: Recaudo junio | E50: =[3]KALA2!M70 -> 55827744
...

Sheet KALIZA T1
D1: UNIDADES VINCULADAS A FIDUCIARIA BANCOLOMBIA | I1: KALIZA 1
D2: VENTAS Y RECURSOS POR FIDEICOMISO
E3: GENERADO 18/06/2026
E6: Cartera de 6 a 30 dias | N6: =N23 -> 0
E7: Catera de 31 a 60dias | N7: =N21 -> 1677600
E8: Cartera de 61 a 90 dias | N8: =N18 -> 9716933
E9: Cartera Mayor de 90 dias | N9: =N13 -> 17627300
B11: CARTERA EN GESTIÓN
B12: NOMENCLATURA | C12: AREA | D12: REFERENCIA | E12: PROPIETARIOS | F12: FECHA CONTRATO | G12: FECHA DE ENTREGA | H12: VALOR VENTA | I12: VALOR M2 | J12: VALOR ABONADO | K12: % RECAUDO | L12: CUOTAS MORA | M12: DIAS MORA | N12: VALOR VENCIDO | O12: OBSERVACIONES
E13: =E9 -> Cartera Mayor de 90 dias | H13: =H14+H15+H16+H17 -> 1861067341 | J13: =+J14+J15++J16+J17 -> 709991971 | N13: =N14+N15+N16+N17 -> 17627300
B14: 5-E | C14: 70.82 | D14: 1603714150505 | E14: LUIS ANDRES GOMEZ HERNANDEZ | F14: 45287 | G14: 46280 | H14: 715282004 | I14: =H14/C14 -> 10100000 | J14: 206516868 | K14: =J14/H14 -> 0.28872091 | L14: 6 | M14: 163 | N14: 6915300 | O14: cliente indica que se le envio notificacion con nueva fecha de entrega en espera de otrosi, se le da contacto de experiencia para que le de la informacion con la nueva fecha de entrega para marzo (valor pendiente es $8.068.900 CI 7 CUOTAS)
B15: 4-L | C15: 48.59 | D15: 1423614141209 | E15: FABIAN DARIO MEJIA FLOREZ | F15: 45355 | G15: 46265 | H15: 323872054 | I15: =H15/C15 -> 6665405.5 | J15: 93781299 | K15: =J15/H15 -> 0.2895628 | L15: 5 | M15: 138 | N15: 2817000 | O15: cliente realiza pagos de una cuota $563.000 se envia recordatorio del saldo (6 CI $3.380.400), se envia recordatorio del valor a la fecha, en espera que confirme el pago
B16: 4-Ñ | C16: 49 | D16: 1423614141502 | E16: KELLY FERNANDA DIAZ GUTIERREZ | F16: 45343 | G16: 46325 | H16: 277177101 | I16: =H16/C16 -> 5656675.5 | J16: 275745519 | K16: =J16/H16 -> 0.99483514 | L16: 5 | M16: 129 | N16: 895000 | O16: Se continua gestion de cartera cliente con saldo total de $1.431.582 CI
B17: 6-H | C17: 89.35 | D17: 1423614160805 | E17: CLAUDIA MARIA COLMENARES | F17: 45103 | G17: 46378 | H17: 544736182 | I17: =H17/C17 -> 6096655.6 | J17: 133948285 | K17: =J17/H17 -> 0.2458957 | L17: 5 | M17: 122 | N17: 7000000 | O17: Cliente se continua gestion de llamadas y envio de recordatorios sin comunicación (8 CI $11,200,000 | P17: el abono que realizo fue de 2300 | Q17: // ENVIAR PREAVISO //
E18: =E8 -> Cartera de 61 a 90 dias | H18: =H19+H20 -> 869218403 | J18: =J19+J20 -> 240274999 | N18: =N19+N20 -> 9716933
B19: 3-B | C19: 55.43 | D19: 1423614130206 | E19: LUIS FERNANDO QUINTERO ZULUAGA PATRICIA ROJAS | F19: 45404 | G19: 46316 | H19: 472398628 | I19: =H19/C19 -> 8522436 | J19: 132284999 | K19: =J19/H19 -> 0.28002833 | L19: 3 | M19: 88 | N19: 5661000 | O19: REALIZO PAGO DE 1 MM en junio se continua gestion
B20: 4-G | C20: 48.59 | D20: 1423614140702 | E20: JHON FREDY SALCEDO HENAO | F20: 45316 | G20: 46239 | H20: 396819775 | I20: =H20/C20 -> 8166696.3 | J20: 107990000 | K20: =J20/H20 -> 0.27213866 | L20: 3 | M20: 73 | N20: 4055933 | O20: cliente realizo pago 2 de junio por valor de $2.100.000 se continua gestion (3 cuotas $ 4.055.933 pendientes CI)
E21: =E7 -> Catera de 31 a 60dias | N21: =N22 -> 1677600
B22: 6-E | C22: 89.35 | D22: 1423614160514 | E22: DANIEL FELIPE UMAÑA DIAZ | F22: 45434 | H22: 845524543 | I22: =H22/C22 -> 9463061.5 | J22: 251295000 | K22: =J22/H22 -> 0.29720604 | L22: 2 | M22: 42 | N22: 1677600 | O22: Se envia recordatorio de pago de saldo cuota de junio pendiente una cuota de CI
E23: =E6 -> Cartera de 6 a 30 dias | H23: =H24 -> 0 | J23: =J24 -> 0 | N23: =N24 -> 0
K24: =J24/H24 -> #DIV/0!
B26: =+COUNTA(B14:B25) -> 7 | E26: TOTALES | H26: =H13+H18+H21+H23 -> 2730285744 | J26: =J13+J18+J21+J23 -> 950266970 | N26: =N13+N18+N21+N23 -> 29021833
B31: NOMENCLATURA | C31: AREA | D31: REFERENCIA | E31: PROPIETARIOS | F31: FECHA CONTRATO | G31: FECHA DE ENTREGA | H31: VALOR VENTA | I31: VALOR M2 | J31: VALOR ABONADO | K31: % RECAUDO | L31: CUOTAS MORA | M31: DIAS MORA | N31: VALOR VENCIDO | O31: OBSERVACIONES
E32: Cartera Mayor de 90 dias | H32: =H34+H33 -> 703002712 | J32: =J34+J33 -> 196783495 | N32: =N34+N33 -> 2081700
B33: 4-M | C33: 48.59 | D33: 1423614141300 | E33: MARIA ELENA TAMAYO GRISALES | F33: 45301 | G33: 46265 | H33: 299247054 | I33: =H33/C33 -> 6158614 | J33: 88885599 | L33: 1 | M33: 5 | N33: 444300 | O33: Cliente solicita descuento por pago en efectivo del valor del apto | Q33: confirmar inf con el cliente
B34: 3-K | C34: 65.57 | D34: 1423614131107 | E34: INGRID MARIA ANAYA LAURENS RAYMOND ERIC TRUFANT | F34: 45449 | G34: 46283 | H34: 403755658 | I34: =H34/C34 -> 6157627.8 | J34: 107897896 | K34: =J34/H34 -> 0.26723563 | L34: 3 | M34: 91 | N34: 1637400 | O34: Cliente solicito a experiencia otro si con ajuste del saldo de la CI $ 2.729.000 (5) cuotas y ajuste de fecha de entrega en dic el valor adeudado lo pagara el 15 de junio | P34: Se nevio notificacion de desistimiento 11 mayo. Cliente realizo la primera cuota el 8 de abril valor de $5.935.000, informa pago el dia 30 de abril los 17 mm Realizar el pago mensual ordinario de $5,935,000 COP antes del 31 de marzo de 2026 y continuar cumpliendo con las mensualidades en las fechas establecidas. Cancelar el saldo pendiente en tres (3) pagos iguales de $17,051,667 COP cada uno, los días 15 de cada mes, así: 15 de abril de 2026 15 de mayo de 2026 15 de junio de 2026 Se envio correo al cliente indicando lo establecido en el comite del 29 de oct y el cliente acepto las condiciones, donde se le dio plazo de 3 meses hasta enero para que nuevamnete inciaria sus pagos y firma de otro si para ajustar el plan de pagos, en el caso de no cumplir se haria desistimiento con la penalidad del 10% (Se le envio correo al cliente recordando que a final de mes de enero se cumple finalizacion de la prorroga, en espera de respuesta del cliente) Cliente informa que no continuara en el proyecto y acepta penalidad 10% esta en proceso
E35: Cartera de 61 a 90 dias | H35: =H36 -> 0 | J35: =J36 -> 0 | N35: =N36 -> 0
I36: =H36/C36 -> #DIV/0! | K36: =J36/H36 -> #DIV/0!
E37: Catera de 31 a 60dias | N37: {=N38:N40} -> 0
N38: 0
N39: 0
E40: Cartera de 6 a 30 dias | H40: =H41 -> 0 | J40: =J41 -> 0 | N40: =N41 -> 0
K41: =J41/H41 -> #DIV/0!
B42: =+COUNTA(B34:B41) -> 1 | E42: TOTALES | H42: =H32+H35+H40 -> 703002712 | J42: =J32+J35+J40 -> 196783495 | N42: =N32+N35+N40 -> 2081700
E44: Total apartamentos torre | F44: 85
E45: Apartamentos en inventario | F45: =F44-F46 -> 1
E46: Numero de Clientes Vinculados | F46: =[4]Hoja2!B87 -> 84
E47: Recaudo Mayo | F47: =[4]Hoja2!L87 -> 76024696
E48: Recaudo junio | F48: =[4]Hoja2!N87 -> 165558003
E49: Recaudo Total a la fecha | F49: =[4]Hoja2!P87 -> 1.5162372e+10
...

Sheet KALIZA T2
D1: UNIDADES VINCULADAS A FIDUCIARIA BANCOLOMBIA | I1: KALIZA 2
D2: VENTAS Y RECURSOS POR FIDEICOMISO
E3: GENERADO 18/06/2026
E6: Cartera de 6 a 30 dias | N6: =N28 -> 3401505
E7: Catera de 31 a 60dias | N7: =N24 -> 2000894
E8: Cartera de 61 a 90 dias | N8: =N19 -> 9542500
E9: Cartera Mayor de 90 dias | N9: =N13 -> 17929179
B11: CARTERA EN GESTIÓN
B12: NOMENCLATURA | C12: AREA | D12: REFERENCIA | E12: PROPIETARIOS | F12: FECHA CONTRATO | G12: FECHA DE ENTREGA | H12: VALOR VENTA | I12: VALOR M2 | J12: VALOR ABONADO | K12: % RECAUDO | L12: CUOTAS MORA | M12: DIAS MORA | N12: VALOR VENCIDO | O12: OBSERVACIONES
E13: =E9 -> Cartera Mayor de 90 dias | H13: =H14+H15+H16+H17 -> 1475872524 | J13: =J14+J15+J16+J17 -> 406385490 | N13: =N14+N15+N16+N17 -> 17929179
B14: 1-Ñ | C14: 55.41 | D14: 1423624211503 | E14: JUAN CAMILO PATIÑO CASTRILLON | F14: 45344 | G14: 46264 | H14: 317399419 | I14: =H14/C14 -> 5728197.4 | J14: 83533418 | K14: =J14/H14 -> 0.26318075 | L14: 4 | M14: 109 | N14: 2677940 | O14: cliente realizo abono de $1.338.970 10 de juni (CI de $3.347.425 5cuotas) | P14: total CI 8
B15: 2-N | C15: 52.26 | D15: 1423624221403 | E15: MONICA MARIA ROJAS ESCOBAR ISABEL CRISTINA MONTOYA SALAZAR MARYORI ALEJANDRA PEREZ BURBANO | F15: 45510 | G15: 46265 | H15: 346516931 | I15: =H15/C15 -> 6630634 | J15: 98668692 | K15: =J15/H15 -> 0.28474422 | L15: 5 | M15: 138 | N15: 4034624 | O15: Cliente solo realizo abono de 340mil 4 de junio se envio comunicado de prorroga con posible entrega para nov (Valor pendiente de la C.I 4.700.000) se envia recordatorio de pago
B16: 4-K | C16: 48.59 | D16: 1423624241114 | E16: RAFAEL NUÑEZ LANDINEZ YAMILE ALBINA FUENTES CARRANZA | F16: 45190 | G16: 46316 | H16: 299247054 | I16: =H16/C16 -> 6158614 | J16: 82596852 | K16: =J16/H16 -> 0.27601559 | L16: 5 | M16: 122 | N16: 5126615 | O16: cliente realizo abono de una cuota 1.025.000 se encunetra en partidas realiza compromiso para el 30 de junio de dos cuotas ya se encuentra en proceso (6 cuotas CI $6.151.938)se continua la gestion de cartera
B17: 5-I | C17: 80.92 | D17: 1423624250909 | E17: SANTIAGO BALAGUERA GARZON | F17: 45182 | G17: 46374 | H17: 512709120 | I17: =H17/C17 -> 6336000 | J17: 141586528 | K17: =J17/H17 -> 0.27615371 | L17: 4 | M17: 109 | N17: 6090000 | O17: Se envia recordatorio si respuesta del cliente de confirmacion (8 cuotas $12.210.000 CI)
K18: =J18/H18 -> #DIV/0!
E19: =E8 -> Cartera de 61 a 90 dias | H19: =H20+H21+H22 -> 1676029226 | J19: =J20+J21+J22 -> 458426512 | N19: =N20+N21+N22 -> 9542500
B20: 5-J | C20: 76.75 | D20: 1423624251002 | E20: INGRID JANNETH PEDRAZA PARDO | F20: 45342 | G20: 46265 | H20: 473832000 | I20: =H20/C20 -> 6173706.8 | J20: 125344195 | K20: =J20/H20 -> 0.26453299 | L20: 3 | M20: 79 | N20: 1155000 | O20: Se envia recordatorio de pago el valor pendiente corresponde a dos de las 3 ultimas cuotas de CI
B21: 3-E | C21: 65.57 | D21: 1423624230503 | E21: MERLIN MONTOYA | F21: 45186 | G21: 46268 | H21: 507375157 | I21: =H21/C21 -> 7737916.1 | J21: 132140445 | K21: =J21/H21 -> 0.26043933 | L21: 3 | M21: 71 | N21: 1142500 | O21: Se envia recordatorio de pago, cliente realiza monetizaciones (el valor pendiente de CI 4 cuotas $2.349.602) se envia recordatorio
B22: 4-H | C22: 80.92 | D22: 1423624240807 | E22: KONSTRUMEK S.A.S MARIA ALEJANDRA TELLO | F22: 45759 | G22: 46304 | H22: 694822069 | I22: =H22/C22 -> 8586530.8 | J22: 200941872 | K22: =J22/H22 -> 0.28919904 | L22: 3 | M22: 69 | N22: 7245000 | O22: Se envia recordatorio de pago (valor pendiente CI $12.060.438 5 cuotas)
B23: 4-M | C23: 48.59 | D23: 1423624241304 | E23: LUIS FELIPE LAMUS HERRERA EDDY YANETH HERRERA LOZADA | F23: 45845 | G23: 46317 | H23: 297333920 | I23: =H23/C23 -> 6119241 | J23: 87264039 | K23: =J23/H23 -> 0.29348834 | L23: 3 | M23: 63 | N23: 1514971 | O23: Se envia recordatorio de pago (valor pendiente CI $2.510.106 5 cuotas) cliente confirma pago total el dia 20 de junio
E24: =E7 -> Catera de 31 a 60dias | H24: =H25+H26+H27 -> 1354902037 | J24: =J25+J26+J27 -> 395214034 | K24: =J24/H24 -> 0.29169196 | N24: =N25+N26+N27 -> 2000894
B25: 4-D | C25: 48.59 | D25: 1423624240403 | E25: DIEGO FERNANDO ORTIZ TERAN | F25: 45287 | G25: 46252 | H25: 402117488 | I25: =I31/C31 -> 8111506 | J25: 119793214 | K25: =J25/H25 -> 0.297906 | L25: 2 | M25: 60 | N25: 495600 | O25: Se envia recordatorio de pago, el valor pendiente corresponde a las 3 ultimas cuotas
B26: 6-H | C26: 89.35 | D26: 1423624260811 | E26: DAVID ALEXANDER BARBOSA MEDINA FABIAN ALBERTO BARBOSA MEDINA | F26: 45465 | G26: 46283 | H26: 619195500 | I26: =H26/C26 -> 6930000 | J26: 183694228 | K26: =J26/H26 -> 0.29666596 | L26: 2 | M26: 48 | N26: 825294 | O26: Se envia recordartorio a la fecha el cliente tiene pendiente 5 cuotas de la CI $2.065.212
B27: 3-Ñ | C27: 55.41 | D27: 1423624231505 | E27: JAVIER FELIPE MOLANO TERAN | F27: 44476 | G27: 46310 | H27: 333589049 | I27: =I32/C32 -> 189405.1 | J27: 91726592 | K27: =J27/H27 -> 0.27496883 | L27: 2 | M27: 33 | N27: 680000 | O27: Se envia recordatorio depago el valor pendiente son las 4 ultimas cuotas de CI $1.350.123
E28: =E6 -> Cartera de 6 a 30 dias | H28: =H29+H30+H31+H32 -> 1516726870 | J28: =J29+J30+J31+J32 -> 485905684 | N28: =N29+N30+N31+N32 -> 3401505
B29: 2-F | C29: 48.59 | D29: 1423624220603 | E29: JHONY MONTEALEGRE MORENO | F29: 45352 | G29: 46353 | H29: 412594911 | I29: =H29/C29 -> 8491354.4 | J29: 116037458 | K29: =J29/H29 -> 0.28123822 | L29: 1 | M29: 30 | N29: 367000 | O29: Se envia recordatorio
B30: 1-K | C30: 55.54 | D30: 1423624211109 | E30: CAMILO FERNANDO ULLOA MAYORGA MARISOL LONDOÑO PALACIO | F30: 44613 | G30: 46323 | H30: 328474384 | I30: =H30/C30 -> 5914194.9 | J30: 85967817 | K30: =J30/H30 -> 0.26171848 | L30: 1 | M30: 20 | N30: 500000 | O30: Se envia recordatorio
B31: 3-D | C31: 65.57 | D31: 1423624230414 | E31: CARLOS RODRIGUEZ | F31: 45354 | G31: 46262 | H31: 328474384 | I31: 531871451 | J31: 160791300 | K31: =J31/H31 -> 0.4895094 | L31: 1 | M31: 20 | N31: 534505 | O31: Se envia recordatorio de pago el valor pendiente corresponde a la ultima cuotas de CI
B32: 2-D | C32: 48.59 | D32: 1423624220413 | E32: NANCY ESPERANZA ALVAREZ GUTIERREZ ) LUIS GERMAN SANCHEZ ROJAS | F32: 45414 | G32: 46358 | H32: 447183191 | I32: =H32/C32 -> 9203193.9 | J32: 123109109 | K32: =J32/H32 -> 0.27529905 | L32: 1 | M32: 15 | N32: 2000000 | O32: Se envia recordatorio
B33: =+COUNTA(B14:B32) -> 15 | E33: TOTALES | H33: =H13+H19+H24+H28 -> 6023530657 | J33: =J13+J19+J24+J28 -> 1745931720 | N33: =N13+N19+N24+N28 -> 32874078
B38: NOMENCLATURA | C38: AREA | D38: REFERENCIA | E38: PROPIETARIOS | F38: FECHA CONTRATO | G38: FECHA DE ENTREGA | H38: VALOR VENTA | I38: VALOR M2 | J38: VALOR ABONADO | K38: % RECAUDO | L38: CUOTAS MORA | M38: DIAS MORA | N38: VALOR VENCIDO | O38: OBSERVACIONES
E39: Cartera Mayor de 90 dias | H39: =H42 -> 0 | J39: =J42 -> 0 | N39: =N42 -> 0
I42: =H42/C42 -> #DIV/0! | K42: =J42/H42 -> #DIV/0! | P42: Se nevio notificacion de desistimiento 11 mayo. Cliente realizo la primera cuota el 8 de abril valor de $5.935.000, informa pago el dia 30 de abril los 17 mm Realizar el pago mensual ordinario de $5,935,000 COP antes del 31 de marzo de 2026 y continuar cumpliendo con las mensualidades en las fechas establecidas. Cancelar el saldo pendiente en tres (3) pagos iguales de $17,051,667 COP cada uno, los días 15 de cada mes, así: 15 de abril de 2026 15 de mayo de 2026 15 de junio de 2026 Se envio correo al cliente indicando lo establecido en el comite del 29 de oct y el cliente acepto las condiciones, donde se le dio plazo de 3 meses hasta enero para que nuevamnete inciaria sus pagos y firma de otro si para ajustar el plan de pagos, en el caso de no cumplir se haria desistimiento con la penalidad del 10% (Se le envio correo al cliente recordando que a final de mes de enero se cumple finalizacion de la prorroga, en espera de respuesta del cliente) Cliente informa que no continuara en el proyecto y acepta penalidad 10% esta en proceso
E43: Cartera de 61 a 90 dias | H43: =H44 -> 0 | J43: =J44 -> 0 | N43: =N44 -> 0
I44: =H44/C44 -> #DIV/0! | K44: =J44/H44 -> #DIV/0!
E45: Catera de 31 a 60dias | N45: {=N46:N48} -> 0
N46: 0
N47: 0
E48: Cartera de 6 a 30 dias | H48: =H49 -> 0 | J48: =J49 -> 0 | N48: =N49 -> 0
K49: =J49/H49 -> #DIV/0!
...

Sheet KALIZA T3
A1: UNIDADES VINCULADAS A FIDUCIARIA BANCOLOMBIA | J1: KALA TORRE 4
A2: VENTAS Y RECURSOS POR FIDEICOMISO
B3: GENERADO 22/06/2026
F6: Cartera de 6 a 30 dias (5) | O6: =O30 -> 6268030
F7: Cartera de 31 a 60 dias (2) | O7: =O50+O23 -> 7886999
F8: Cartera de 61 a 90 dias (4) | O8: =O16 -> 34074000
F9: Cartera Mayor de 90 dias (0) | O9: 0
A11: CARTERA EN GESTIÓN
A12: INVENTARIO | B12: INMUEBLE | C12: NOMENCLATURA | D12: AREA | E12: REFERENCIA | F12: PROPIETARIOS | G12: FECHA CONTRATO | H12: FECHA DE ENTREGA | I12: VALOR VENTA | J12: VALOR M2 | K12: VALOR ABONADO | L12: % RECAUDO | M12: CUOTAS MORA | N12: DIAS MORA | O12: VALOR VENCIDO | P12: OBSERVACIONES
F13: =F9 -> Cartera Mayor de 90 dias (0)
A14: KALIZA 3 | J14: =I14/D14 -> #DIV/0! | L14: =K14/I14 -> #DIV/0!
A15: KALIZA 3 | J15: =I15/D15 -> #DIV/0! | L15: =K15/I15 -> #DIV/0!
F16: =F8 -> Cartera de 61 a 90 dias (4) | I16: =I17+I18+I19+I20 -> 2245922572 | K16: =K17+K18+K19+K20 -> 4.4155481e+08 | O16: =O17+O18+O19+O20 -> 34074000
A17: KALIZA 3 | B17: 5-L | C17: 43512 | D17: 70.82 | E17: 1423634351210 | F17: _x000D_21016297 LUZ HELENA HERNANDEZ GARCIA (100.00%) | G17: 44656 | H17: 20/03/2028 | I17: 499393366 | J17: =I17/D17 -> 7051586.6 | K17: 114726450 | L17: =K17/I17 -> 0.22973163 | M17: 3 | N17: 89 | O17: 2948000 | P17: Cliente informa que esta efectuando pagos todos los 10 de cada mes, pero no por la totalidad, que en cuento pueda se coloca al dia, Realizara pago junio 10
A18: KALIZA 3 | B18: 3-E | C18: 43305 | D18: 65.57 | E18: 1423634330519 | F18: _x000D_1125790279 JONATHAN ORTIZ HERRERA (50.00%) _x000D_5596723383 TATIANA GIRALDO (50.00%) | G18: 44575 | H18: 21/02/2028 | I18: 514374361 | J18: =I18/D18 -> 7844660.1 | K18: 95011010 | L18: =K18/I18 -> 0.18471179 | M18: 3 | N18: 88 | O18: 5226000 | P18: Cliente no responde las llamadas, se envio recordatorio de pago, se continua gestion de cobro por todos los canales
A19: KALIZA 3 | B19: 1-B | C19: 43102 | D19: 55.41 | E19: 1423634310214 | F19: 901426704 UMBRELLA ORGANIZATION SAS | G19: 44678 | H19: 46751 | I19: 520275150 | J19: =I19/D19 -> 9389553.3 | K19: 115337575 | L19: =K19/I19 -> 0.22168573 | M19: 3 | N19: 79 | O19: 4836000 | P19: Compromiso de pago 02 de Junio 2026, INCUMPLIO COMPROMISO
A20: KALIZA 3 | B20: 2-H | C20: 43208 | D20: 80.92 | E20: 1423614320805 | F20: _x000D_43616216 BIBIANA VALENCIA GOMEZ (100.00%) | G20: 45329 | H20: 46782 | I20: 711879695 | J20: =I20/D20 -> 8797326.9 | K20: 1.1647977e+08 | L20: =K20/I20 -> 0.16362283 | M20: 3 | N20: 79 | O20: 21064000 | P20: Compromiso de pago 02 de Junio 2026, INCUMPLIO COMPROMISO
J21: =I21/D21 -> #DIV/0! | L21: =K21/I21 -> #DIV/0!
J22: =I22/D22 -> #DIV/0! | L22: =K22/I22 -> #DIV/0!
F23: =F7 -> Cartera de 31 a 60 dias (2) | I23: =I24+I25+I27 -> 1538184357 | J23: =I23/D23 -> #DIV/0! | K23: =K24+K25+K27 -> 321761929 | O23: =O24+O25+O27 -> 6910999
A24: KALIZA 3 | B24: 5E | C24: 43505 | D24: 70.82 | E24: 1423634350511 | F24: _x000D_1152186522 ESTEBAN HIGUITA PEREZ (100.00%) | G24: 44565 | H24: 46888 | I24: 604226317 | J24: =I24/D24 -> 8531859.9 | K24: 134709645 | L24: =K24/I24 -> 0.22294568 | M24: 2 | N24: 33 | O24: 2528000 | P24: Compromiso de pago primera semana de Julio
A25: KALIZA 3 | B25: 5-M | C25: 43513 | D25: 48.59 | E25: 1423634351311 | F25: _x000D_901260287 GRUPO UNION INMOBILIARIA SAS (100.00%) | G25: 44579 | H25: 21/03/2028 | I25: 286284133 | J25: =I25/D25 -> 5891832.3 | K25: 35581041 | L25: =K25/I25 -> 0.12428576 | O25: 2178999 | P25: Realizo abono de $1MM , se continua la gestion de cartera
A26: KALIZA 3 | B26: 5I | C26: 43509 | D26: 80.92 | E26: 1423634350915 | F26: 1220465381 YURLEY DANIELA BERDUGO TREJO | G26: 44593 | H26: 46888 | I26: 493401154 | J26: =I26/D26 -> 6097394.4 | K26: 107493941 | L26: =K26/I26 -> 0.21786317 | M26: 2 | N26: 33 | O26: 2003483 | P26: Realiza pago de una cuota Junio 30 de 2026
A27: KALIZA 3 | B27: 6L | C27: 43612 | D27: 92.76 | E27: 1423634361211 | F27: 52515537 MYRIAM PATRICIA COTAMO VESGA 79626629 JUAN CARLOS MAYORGA MEDINA ( | G27: 44595 | H27: 46884 | I27: 647673907 | J27: =I27/D27 -> 6982254.3 | K27: 151471243 | L27: =K27/I27 -> 0.23386961 | M27: 2 | N27: 37 | O27: 2204000 | P27: Realizara pago de una cuota Julio 4 y la,otra Julio 30
J29: =I29/D29 -> #DIV/0! | L29: =K29/I29 -> #DIV/0!
F30: =F6 -> Cartera de 6 a 30 dias (5) | I30: =I31+I37 -> 296735920 | K30: =K31+K37 -> 62391380 | O30: =O31+O37+O32+O33+O34+O35+O36 -> 6268030
A31: KALIZA 3 | B31: 2N | C31: 43214 | D31: 52.26 | E31: 1423634321419 | F31: _x000D_32649418 CARMEN ALICIA GARCIA LOZANO (50.00%) _x000D_8735880 JAIME ORLANDO MONTOYA CANO (50.00%) | G31: 44579 | H31: 46837 | I31: 296735920 | J31: =I31/D31 -> 5678069.7 | K31: 62391380 | L31: =K31/I31 -> 0.21025894 | M31: 1 | N31: 23 | O31: 435000 | P31: Realiza pago Julio 5 de 2026
A32: KALIZA 3 | B32: 4I | C32: 43409 | D32: 80.9 | E32: 1423634340914 | F32: 16629281 CARLOS HUMBERTO NAVIA ESTRADA | G32: 44573 | H32: 46862 | I32: 517815974 | J32: =I32/D32 -> 6400691.9 | K32: 106856950 | L32: =K32/I32 -> 0.20636086 | M32: 1 | N32: 29 | O32: 1409000 | P32: Realizara Pago la primera semana de julio
A33: KALIZA 3 | B33: 4G | C33: 43407 | D33: 76.75 | E33: 1423634340712 | F33: 1010182149 ANDRES VILLAMIL PINZON | G33: 44572 | H33: 46679 | I33: 642305094 | J33: =I33/D33 -> 8368796 | K33: 159191570 | L33: =K33/I33 -> 0.24784417 | M33: 1 | N33: 29 | O33: 645000 | P33: Se envio recordatorio de pago
A34: KALIZA 3 | B34: 1A | C34: 43101 | D34: 80.92 | E34: 1423634310113 | F34: _x000D_51833524 SANDRA LEONORA DIAZ GUTIERREZ (50.00%) _x000D_72152859 GERARDO VARGAS BAENA (50.00%) | G34: 44573 | H34: 46803 | I34: 684927994 | J34: =I34/D34 -> 8464260.9 | K34: 162719868 | L34: =K34/I34 -> 0.23757223 | M34: 1 | N34: 28 | O34: 676000 | P34: Se envio recordatorio de pago
A35: KALIZA 3 | B35: 5J | C35: 43510 | D35: 76.75 | E35: 1423634351018 | F35: 42008897 EMILSEN YANETH GUARIN ALARCON | G35: 44582 | H35: 46325 | I35: 466686710 | J35: =I35/D35 -> 6080608.6 | K35: 116513690 | L35: =K35/I35 -> 0.24966147 | M35: 1 | N35: 17 | O35: 1212030 | P35: Se envio recordatorio de pago
A36: KALIZA 3 | B36: 1-J | C36: 43110 | D36: 83.31 | E36: 1423634311014 | F36: _x000D_35507912 NELLY CECILIA ALBANCANDO CUSHCAGUA (100.00%) | G36: 44609 | H36: 25/12/2027 | I36: 479564474 | J36: =I36/D36 -> 5756385.5 | K36: 88549374 | L36: =K36/I36 -> 0.1846454 | M36: 1 | N36: 23 | O36: 1891000 | P36: Realizo abono de 2.1MM , se continua con la gestion de cartera
J37: =I37/D37 -> #DIV/0! | L37: =K37/I37 -> #DIV/0!
C38: =+COUNTA(C17:C37) -> 14 | F38: TOTALES | I38: =I16+I23+I30 -> 4080842849 | K38: =K16+K23+K30 -> 8.2570811e+08 | O38: =O16+O23+O30 -> 47253029
A42: CARTERA EN TRAMITE
A43: INVENTARIO | B43: INMUEBLE | C43: NOMENCLATURA | D43: AREA | E43: REFERENCIA | F43: PROPIETARIOS | G43: FECHA CONTRATO | H43: FECHA DE ENTREGA | I43: VALOR VENTA | J43: VALOR M2 | K43: VALOR ABONADO | L43: % RECAUDO | M43: CUOTAS MORA | N43: DIAS MORA | O43: VALOR VENCIDO | P43: OBSERVACIONES
F44: Cartera Mayor de 90 dias
A45: KALIZA 3 | J45: =I45/D45 -> #DIV/0! | L45: =K45/I45 -> #DIV/0!
A46: KALIZA 3 | J46: =I46/D46 -> #DIV/0! | L46: =K46/I46 -> #DIV/0!
A47: KALIZA 3 | F47: Cartera de 61 a 90 dias | O47: {=O48:O49} -> 0
...

Sheet KALA T3
C1: UNIDADES VINCULADAS A FIDUCIARIA BANCOLOMBIA | H1: KALA GOLF 3
C2: VENTAS Y RECURSOS POR FIDEICOMISO
D3: GENERADO 18/06/2026
D6: Cartera de 6 a 30 dias | M6: =M27 -> 9608000
D7: Catera de 31 a 60dias | M7: =M21 -> 17485945
D8: Cartera de 61 a 90 dias | M8: =M19 -> 4275000
D9: Cartera Mayor de 90 dias | M9: =M13 -> 88315995
A11: CARTERA EN GESTIÓN
A12: NOMENCLATURA | B12: AREA | C12: REFERENCIA | D12: PROPIETARIOS | E12: FECHA CONTRATO | F12: FECHA DE ENTREGA | G12: VALOR VENTA | H12: VALOR M2 | I12: VALOR ABONADO | J12: % RECAUDO | K12: CUOTAS MORA | L12: DIAS MORA | M12: VALOR VENCIDO | N12: OBSERVACIONES
D13: =D9 -> Cartera Mayor de 90 dias | G13: =G17+G18+G16+G15 -> 1866881716 | I13: =I17+I18+I16+I15 -> 433373614 | M13: =M17+M18+M16+M15+M14 -> 88315995
A14: 5-A | B14: 114.6 | C14: 1429635450101 | D14: JORGE MAURICIO MELO YEPES | E14: 45695 | F14: 46517 | G14: 1088802813 | H14: =G14/B14 -> 9500897.1 | I14: 210782773 | J14: =I14/G14 -> 0.19359132 | K14: 9 | L14: 250 | M14: 53025000 | N14: Cliente realizo abono de 10 mm en junio y confirma pago de 1o mm el 26 junio para proceder a realizar otro si
A15: 2-Ñ | B15: 50.82 | C15: 1429635421504 | D15: IVAN DARIO VALBUENA ARANGO | E15: 45754 | F15: 46522 | G15: 343126476 | H15: =G15/B15 -> 6751800 | I15: 82391061 | J15: =I15/G15 -> 0.24011863 | K15: 6 | L15: 153 | M15: 6450000 | N15: Se envio Preaviso con fecha hasta el 11 junio, cliente sin respuesta de recordatorios y preaviso | P15: se comunico hoy solicita que se hay la posibilidad que haga una refinanciacion de la ci | Q15: pague 50% para hacer reajuste
A16: 1-I | B16: 64.9 | C16: 1429635410905 | D16: MARIA MONICA BUENDIA ULLOA VICTORIA ANDREA OCAMPO GRAJALES | E16: 45761 | F16: 46507 | G16: 609808845 | H16: =G16/B16 -> 9396130.1 | I16: 138772553 | J16: =I16/G16 -> 0.2275673 | K16: 5 | L16: 138 | M16: 12769995 | N16: cliente solicita espera para realizar pago total adeudado la primera semana de junio, no cumplio con compromiso, solo realizo pago de 2 mm en junio | P16: preaviso
A17: 3-Ñ | B17: 50.94 | C17: 1429635431505 | D17: DORIS JANNETH PATIÑO MADROÑERO MARIO ALEXANDER RAMOS RAMOS | E17: 45695 | F17: 46507 | G17: 355558881 | H17: =G17/B17 -> 6979954.5 | I17: 77110000 | J17: =I17/G17 -> 0.21686985 | K17: 4 | L17: 109 | M17: 8540000 | N17: Se envio Notificacion de desistimiento 22 de mayo, cliente realiza abono de $8,540,000 1 de junio solicita espera el 30 de junio, le informe que debia realizar pagos adicionales antes del 30 de junio | O17: total CI 8
A18: 5-K | B18: 71.42 | C18: 1429635451103 | D18: LEONARDO TABARES OSORIO | E18: 45780 | F18: 46599 | G18: 558387514 | H18: =G18/B18 -> 7818363.4 | I18: 135100000 | J18: =I18/G18 -> 0.24194667 | K18: 4 | L18: 109 | M18: 7531000 | N18: cliente pendiente valor cuota de 5mm para terminar pago de compromisos y continuar con su gestion de cartera | O18: se le envio recordatorio 15 de mayo la respuesta es que se encuentra en tramite de leasing y le informe que el credito es un valor aparte de la CI
D19: =D8 -> Cartera de 61 a 90 dias | G19: =G20 -> 511382487 | I19: =I20 -> 136334050 | M19: =M20 -> 4275000
A20: 3-K | B20: 65.36 | C20: 1429635431101 | D20: ANDREA YADIRA GRANADOS MARTINEZ | E20: 45769 | F20: 46553 | G20: 511382487 | H20: =G20/B20 -> 7824089.5 | I20: 136334050 | J20: =I20/G20 -> 0.26659898 | K20: 3 | L20: 63 | M20: 4275000 | N20: Se envia recordatorio de pago
D21: =D7 -> Catera de 31 a 60dias | G21: =G24+G25+G23+G22 -> 2240174706 | I21: =I24+I25+I23+I26+I22 -> 570505351 | J21: =I21/G21 -> 0.25467003 | M21: =M24+M25+M23+M22 -> 17485945
A22: 1-B | B22: 55.22 | C22: 1429635410222 | D22: JENNIFER LIZETH NAVARRO JARAMILLO | E22: 45761 | F22: 46468 | G22: 550000000 | H22: =G22/B22 -> 9960159.4 | I22: 145560000 | J22: =I22/G22 -> 0.26465455 | K22: 2 | L22: 56 | M22: 3780000 | N22: Se envia recordatorio de pago
A23: 2-D | B23: 97.54 | C23: 1429635420401 | D23: ROCIO DEL PILAR GARCIA HERNANDEZ (12.50%) 28869349 LINDA JHOANA GARCIA HERNANDEZ (12.50%) BLANCA RUTH HERNANDEZ DE GARCIA LUIS ALBERTO MONTALVAN BAZAN BETSY ARACELI MONTALVAN BAZAN DE ALLEN TIMOTHY DONALD ALLEN LUIS HUMBERTO ENRIQUEZ 1023923440 MARIA ELIZABETH CASTRO CARDENAS (12.50%) | E23: 44861 | F23: 46538 | G23: 890548800 | H23: =G23/B23 -> 9130088.2 | I23: 233720971 | J23: =I23/G23 -> 0.262446 | K23: 2 | L23: 48 | M23: 4168945 | N23: Se envia recordatorio de pago,. Cliente confirma pago para el dia 26 de junio
A24: 2-B | B24: 53.06 | C24: 1429635420211 | D24: ADA RUTH MARGARI ARIZA AGUILAR JAIME EDUARDO PEÑA MEDINA | E24: 45719 | F24: 46455 | G24: 444452296 | H24: =G24/B24 -> 8376409.6 | I24: 94127380 | J24: =I24/G24 -> 0.21178286 | K24: 2 | L24: 41 | M24: 8120000 | N24: Se envia recordatorio, en espera de confrimacion pago cuota realizo abono de 4 en junio 4,060mm
A25: 5-M | B25: 49.1 | C25: 1429635451305 | D25: DIANA CAROLINA BELLON | E25: 44806 | F25: 46576 | G25: 355173610 | H25: =G25/B25 -> 7233678.4 | I25: 97097000 | J25: =I25/G25 -> 0.27337898 | K25: 2 | L25: 40 | M25: 1417000 | N25: Se envia recordatorio de pago cliente se comunica quiere validar pagos
D27: =D6 -> Cartera de 6 a 30 dias | G27: =G28+G29+G32+G30+G31 -> 3082683965 | I27: =I28+I29+I32+I30+I31 -> 796353976 | M27: =M28+M29+M32+M30+M31 -> 9608000
A28: 3-B | B28: 53.58 | C28: 1429635430200 | D28: JENIFFER JULIET GUZMAN OSPINA CRISTIAN CAMILO CUERVO RUIZ HENRY GUERRERO SOSA | E28: 45789 | F28: 46561 | G28: 526326200 | H28: =G28/B28 -> 9823184 | I28: 144830000 | J28: =I28/G28 -> 0.27517156 | K28: 1 | L28: 25 | M28: 1089000 | N28: Se envia recordatorio de pago
A29: 5-F | B29: 113.58 | C29: 1429635450618 | D29: LEONARDO MONTAÑEZ MELGAREJO | E29: 45710 | F29: 46537 | G29: 1093389931 | H29: =G29/B29 -> 9626606.2 | I29: 277404742 | J29: =I29/G29 -> 0.25371072 | K29: 1 | L29: 18 | M29: 4235000 | N29: Se envia recordatorio de pago
A30: 1-L | B30: 55.4 | C30: 1429635411200 | D30: CARLOS ARTURO RAMIREZ JIMENEZ | E30: 45763 | F30: 46507 | G30: 408410000 | H30: =G30/B30 -> 7372021.7 | I30: 107045600 | J30: =I30/G30 -> 0.26210328 | K30: 1 | L30: 17 | M30: 332000 | N30: Se envia recordatorio de pago
A31: 1-M | B31: 71.42 | C31: 1429635450505 | D31: MONICA STELLA GOMEZ CALA 93386580 JORGE IVAN MORENO MARTINEZ (50.00%) | E31: 44718 | F31: 46599 | G31: 693594504 | H31: =G31/B31 -> 9711488.4 | I31: 174966332 | J31: =I31/G31 -> 0.25226026 | K31: 1 | L31: 17 | M31: 2682000 | N31: Se envia recordatorio de pago
A32: 1-M | B32: 50 | C32: 1429635411301 | D32: MONICA VANEGAS SOTO | E32: 45674 | F32: 46452 | G32: 360963330 | H32: =G32/B32 -> 7219266.6 | I32: 92107302 | J32: =I32/G32 -> 0.2551708 | K32: 1 | L32: 11 | M32: 1270000 | N32: Se envia recordatorio de pago
A33: =+COUNTA(A17:A32) -> 12 | D33: TOTALES | G33: =G13+G19+G21+G27 -> 7701122874 | I33: =I13+I19+I21+I27 -> 1936566991 | M33: =M13+M19+M21+M27 -> 119684940
A38: NOMENCLATURA | B38: AREA | C38: REFERENCIA | D38: PROPIETARIOS | E38: FECHA CONTRATO | F38: FECHA DE ENTREGA | G38: VALOR VENTA | H38: VALOR M2 | I38: VALOR ABONADO | J38: % RECAUDO | K38: CUOTAS MORA | L38: DIAS MORA | M38: VALOR VENCIDO | N38: OBSERVACIONES
D39: Cartera Mayor de 90 dias | G39: =G40 -> 0 | I39: =I40 -> 0 | M39: =M40 -> 0
H40: =G40/B40 -> #DIV/0! | J40: =I40/G40 -> #DIV/0! | O40: Se nevio notificacion de desistimiento 11 mayo. Cliente realizo la primera cuota el 8 de abril valor de $5.935.000, informa pago el dia 30 de abril los 17 mm Realizar el pago mensual ordinario de $5,935,000 COP antes del 31 de marzo de 2026 y continuar cumpliendo con las mensualidades en las fechas establecidas. Cancelar el saldo pendiente en tres (3) pagos iguales de $17,051,667 COP cada uno, los días 15 de cada mes, así: 15 de abril de 2026 15 de mayo de 2026 15 de junio de 2026 Se envio correo al cliente indicando lo establecido en el comite del 29 de oct y el cliente acepto las condiciones, donde se le dio plazo de 3 meses hasta enero para que nuevamnete inciaria sus pagos y firma de otro si para ajustar el plan de pagos, en el caso de no cumplir se haria desistimiento con la penalidad del 10% (Se le envio correo al cliente recordando que a final de mes de enero se cumple finalizacion de la prorroga, en espera de respuesta del cliente) Cliente informa que no continuara en el proyecto y acepta penalidad 10% esta en proceso
D41: Cartera de 61 a 90 dias
D43: Catera de 31 a 60dias | M43: {=M44:M46} -> 0
M44: 0
M45: 0
D46: Cartera de 6 a 30 dias | G46: =G47 -> 0 | I46: =I47 -> 0 | M46: =M47 -> 0
J47: =I47/G47 -> #DIV/0!
A48: =+COUNTA(A40:A47) -> 0 | D48: TOTALES | F48: =SUM(F42:F47) -> 0 | G48: =G39+G46 -> 0 | I48: =I39+I46 -> 0 | M48: =M39 -> 0
D50: Total apartamentos torre | E50: 66
...

Sheet KALA T4
A1: UNIDADES VINCULADAS A FIDUCIARIA BANCOLOMBIA | J1: KALA TORRE 4
A2: VENTAS Y RECURSOS POR FIDEICOMISO
B3: GENERADO 22/06/2026
A6: CARTERA EN GESTIÓN | F6: Cartera de 6 a 30 dias (3) | O6: =O36 -> 6368000
F7: Cartera de 31 a 60 dias (8) | O7: =O26 -> 46299686
F8: Cartera de 61 a 90 dias (6) | O8: =O18 -> 68995724
F9: Cartera Mayor de 90 dias (4) | O9: =O13+O47 -> 40332717
A12: INVENTARIO | B12: INMUEBLE | C12: NOMENCLATURA | D12: AREA | E12: REFERENCIA | F12: PROPIETARIOS | G12: FECHA CONTRATO | H12: FECHA DE ENTREGA | I12: VALOR VENTA | J12: VALOR M2 | K12: VALOR ABONADO | L12: % RECAUDO | M12: CUOTAS MORA | N12: DIAS MORA | O12: VALOR VENCIDO | P12: OBSERVACIONES
F13: =F9 -> Cartera Mayor de 90 dias (4) | I13: =I14+I15+I16 -> 2744055216 | K13: =K14+K15+K16 -> 721278309 | O13: =O14+O15+O16 -> 30782717
A14: KALA 4 | B14: 4-C | C14: 53403 | D14: 70.77 | E14: 1429645340326 | F14: _x000D_5006642413 JOSEPH FILI (100.00%) | G14: 45835 | H14: 46560 | I14: 715986417 | J14: =I14/D14 -> 10117089 | K14: 210153208 | L14: =K14/I14 -> 0.29351564 | M14: 1 | N14: 169 | O14: 4642717 | P14: Compromiso de pago 15 de Junio 2026, se hace gestion constante sin tener respuesta del cliente
A15: KALA 4 | B15: 2-A | C15: 53405 | D15: 70.82 | E15: 1429645340504 | F15: _x000D_66977878 SANDRA DURLEY MURILLO CAMPO (100.00%) | G15: 45761 | H15: 46492 | I15: 696031701 | J15: =I15/D15 -> 9828179.9 | K15: 179240975 | L15: =K15/I15 -> 0.25751841 | M15: 4 | N15: 94 | O15: 7300000 | P15: Compromiso de pago 03 de Junio 2026, INCUMPLIO COMPROMISO , se continua gestion
A16: KALA 4 | B16: 6-J | C16: 53301 | D16: 145.34 | E16: 1429645330109 | F16: _x000D_1125778908 PETER JOSEPH GUADAGNINO BITAR (50.00%) _x000D_52145246 ILEANA JOSEFINA MONTES BITAR (50.00%) | G16: 45714 | H16: 46489 | I16: 1332037098 | J16: =I16/D16 -> 9164972.5 | K16: 331884126 | L16: =K16/I16 -> 0.24915532 | M16: 4 | N16: 97 | O16: 18840000 | P16: Clientes no responden las llamadas, se solicito colaboracion con su asesora Karen, en espera de respuesta, AUN SIN RESPUESTA PORQUE EL CLIENTE NO CONTESTA
A17: KALA 4 | J17: =I17/D17 -> #DIV/0! | L17: =K17/I17 -> #DIV/0!
F18: =F8 -> Cartera de 61 a 90 dias (6) | I18: =I19+I20+I21+I22+I23+I24 -> 4524909768 | K18: =K19+K20+K21+K22+K23+K24 -> 999120867 | O18: =O19+O20+O21+O22+O23+O24 -> 68995724
A19: KALA 4 | B19: 3-I | C19: 53309 | D19: 88.72 | E19: 1429645330907 | F19: _x000D_19265399 JAIME ANTONIO AMAYA PARDO (100.00%) | G19: 45762 | H19: 46540 | I19: 640388470 | J19: =I19/D19 -> 7218084.6 | K19: 154743194 | L19: =K19/I19 -> 0.24163957 | M19: 3 | N19: 76 | O19: 6061176 | P19: Molestos por la gestion de cobro, indican que tambien estamos en mora con la entrega, que visitaron el proyecto y esta super atrasado, compromiso 30 de Mayo 1 cuota, realizo junio 16 pago por $3MM
A20: KALA 4 | B20: 4-L | C20: 53412 | D20: 48.59 | E20: 1429645341203 | F20: _x000D_25213512 LUZ ALICIA ABELLO HINCAPIE (100.00%) | G20: 44676 | H20: 46499 | I20: 333018762 | J20: =I20/D20 -> 6853648.1 | K20: 87429347 | L20: =K20/I20 -> 0.2625358 | M20: 3 | N20: 79 | O20: 4130653 | P20: Compromiso de pago 02 de Junio 2026, INCUMPLIO ; Nuevo Compromiso Junio 30 una cuota y junio 15 se coloca al dia
A21: KALA 4 | B21: 5-A | C21: 53501 | D21: 140.13 | E21: 1429645350101 | F21: _x000D_73212741 DANIEL ANTONIO MUVDI LOPEZ (100.00%) | G21: 45761 | H21: 46538 | I21: 1346194869 | J21: =I21/D21 -> 9606757.1 | K21: 317531591 | L21: =K21/I21 -> 0.23587342 | M21: 3 | N21: 79 | O21: 17757000 | P21: Cliente cancela cada 3 meses, lo realizara la primera semana de Julio
A22: KALA 4 | B22: 4-K | C22: 53610 | D22: 89.55 | E22: 1429645361003 | F22: _x000D_1022966672 YILVER ESNAYDER AVILA GALINDO (50.00%) _x000D_52298479 YANETH VIVIANA LOPEZ BOCANEGRA (50.00%) | G22: 45754 | H22: 46522 | I22: 658763435 | J22: =I22/D22 -> 7356375.6 | K22: 142016007 | L22: =K22/I22 -> 0.21557967 | M22: 3 | N22: 63 | O22: 14369995 | P22: Compromiso de pago 30 de Junio con la prima.
A23: KALA 4 | B23: 6-F | C23: 53606 | D23: 89.85 | E23: 1429645360607 | F23: 40049109 MERY JOHANNA GONZALEZ ALBA (50.00%) 71713240 PEDRO YESID LIZARAZO MARTINEZ (50.00%) | G23: 44855 | H23: 46767 | I23: 906345816 | J23: =I23/D23 -> 10087321 | K23: 142000000 | L23: =K23/I23 -> 0.15667309 | M23: 3 | N23: 63 | O23: 19356900 | P23: Cliente estaba pensando en ceder el apartamento, Claudia informa que no esta en proceso y no ha firmado la promesa, cliente no responde las llamadas // ENVIAR CORREO POR EL TEMA DE LA CESION //AUN SIN RESPUESTA
A24: KALA 4 | B24: 2-I | C24: 53209 | D24: 88.72 | E24: 1429645320920 | F24: _x000D_1061689685 JAVIER HERNAN CABRERA HERRERA (100.00%) | G24: 45695 | H24: 46507 | I24: 640198416 | J24: =I24/D24 -> 7215942.5 | K24: 155400728 | L24: =K24/I24 -> 0.24273838 | M24: 3 | N24: 79 | O24: 7320000 | P24: Cliente cancela los 20 de cada mes, pero no ha efectuado pagos, quedo en confirmar las fechas de programacion de pagos, PAGA DOS CUOTAS JULIO 20
J25: =I25/D25 -> #DIV/0! | L25: =K25/I25 -> #DIV/0!
F26: =F7 -> Cartera de 31 a 60 dias (8) | I26: =I27+I28+I29+I30+I31+I32+I33+I34 -> 4578280581 | K26: =K27+K28+K29+K30+K31+K32+K33+K34 -> 1105420504 | O26: =O27+O28+O29+O30+O31+O32+O33+O34 -> 46299686
A27: KALA 4 | B27: 3-N | C27: 53314 | D27: 55.56 | E27: 1429645331416 | F27: _x000D_1144035807 GUILLERMO ALEJANDRO RODRIGUEZ HOLGUIN (50.00%) _x000D_1144058134 EDUARDO MARIN TORO (50.00%) | G27: 45799 | H27: 46540 | I27: 389078004 | J27: =I27/D27 -> 7002843.8 | K27: 90008000 | L27: =K27/I27 -> 0.23133664 | M27: 2 | N27: 46 | O27: 4456000 | P27: Compromiso de pago 30 de Junio 2026.
A28: KALA 4 | B28: 3-E | C28: 53305 | D28: 65.57 | E28: 1429645330503 | F28: _x000D_5118868888 WILLER OMAR GALVAN MEJIA (100.00%) | G28: 45761 | H28: 46492 | I28: 574970216 | J28: =I28/D28 -> 8768800 | K28: 142807306 | L28: =K28/I28 -> 0.2483734 | M28: 2 | N28: 33 | O28: 5868668 | P28: Ingreso Monetizacion Junio 18 , proximo pago Julio 15
A29: KALA 4 | B29: 3J | C29: 53310 | D29: 65.57 | E29: 1429645331000 | F29: _x000D_53177363 LEIDY DAYANA SANDOVAL ROJAS (50.00%) _x000D_5643632973 JOSEPH LEE ALGIERE (50.00%) | G29: 45716 | H29: 46487 | I29: 464366459 | J29: =I29/D29 -> 7081995.7 | K29: 131211225 | L29: =K29/I29 -> 0.28255965 | M29: 2 | N29: 38 | O29: 959999 | P29: Compromiso de pago 10 de julio 2026
A30: KALA 4 | B30: 3-F | C30: 53306 | D30: 65.57 | E30: 1429645330604 | F30: _x000D_43598985 MARLA YARLEY RAMIREZ TOBON (100.00%) | G30: 45700 | H30: 46511 | I30: 612577576 | J30: =I30/D30 -> 9342345.2 | K30: 135166307 | L30: =K30/I30 -> 0.22065174 | M30: 2 | N30: 44 | O30: 5000000 | P30: Compromiso de pago 30de Junio 2026.
A31: KALA 4 | B31: 5-L | C31: 53512 | D31: 70.82 | E31: 1429645351216 | F31: _x000D_79483596 JOSE WILLIAM HORTA VANEGAS (100.00%) | G31: 45761 | H31: 46514 | I31: 573636862 | J31: =I31/D31 -> 8099927.4 | K31: 163723966 | L31: =K31/I31 -> 0.28541396 | M31: 2 | N31: 41 | O31: 1520000 | P31: Compromiso de pago 30 de Junio 2026.
A32: KALA 4 | B32: 1-H | C32: 53108 | D32: 88.74 | E32: 1429645310804 | F32: _x000D_5003154818 LUIS BUITRAGO (50.00%) _x000D_5004141420 WILDA TRINIDAD DIAZ (50.00%) | G32: 45720 | H32: 46464 | I32: 783908255 | J32: =I32/D32 -> 8833764.4 | K32: 195913007 | L32: =K32/I32 -> 0.24991829 | M32: 2 | N32: 60 | O32: 6780000 | P32: Compromiso de pago 04 de Junio 2026, NO CUMPLIO , nuevo compromiso primera semana de julio
A33: KALA 4 | B33: 4-O | C33: 53416 | D33: 8664 | E33: 1429645341607 | F33: _x000D_900614957 I VOLUCION PROYECTOS PARA EL DESARROLLO SAS (100.00%) | G33: 45762 | H33: 46560 | I33: 670053000 | J33: =I33/D33 -> 77337.604 | K33: 131590693 | L33: =K33/I33 -> 0.19638848 | M33: 2 | N33: 35 | O33: 9729269 | P33: Compromiso de pago 05 de Julio 2026.
A34: KALA 4 | B34: 5-N | C34: 53514 | D34: 52.25 | E34: 1429645351432 | F34: _x000D_26421728 MARIA ANGELICA VANEGAS MOTTA (100.00%) | G34: 45638 | H34: 46381 | I34: 509690209 | J34: =I34/D34 -> 9754836.5 | K34: 115000000 | L34: =K34/I34 -> 0.22562725 | M34: 2 | N34: 46 | O34: 11985750 | P34: Compromiso de pago 03 de Junio $7 millones y $12 millones el 05 de Junio 2026., REALIZO PAGO PARCIAL DE $9MM , NUEVAMENTE SE GESTIONA PROXIMO PAGO
F36: =F6 -> Cartera de 6 a 30 dias (3) | I36: =I37+I38+I39+I40 -> 1773484903 | K36: =K37+K38+K39+K40 -> 461063588 | O36: =O37+O38+O39+O40 -> 6368000
A37: KALA 4 | B37: 2Ñ | C37: 53215 | D37: 48.7 | E37: 1429645321504 | F37: _x000D_42123725 CLAUDIA MILENA HINCAPIE ZAPATA (100.00%) | G37: 45769 | H37: 46464 | I37: 341614529 | J37: =I37/D37 -> 7014672.1 | K37: 81428860 | L37: =K37/I37 -> 0.23836474 | M37: 1 | N37: 30 | O37: 2430000 | P37: Compromiso de pago 15 de Julio 2026.
A38: KALA 4 | B38: 1M | C38: 53113 | D38: 55.54 | E38: 1429645311301 | F38: _x000D_91272706 FLAMINIO GUARIN ARENAS (100.00%) | G38: 45784 | H38: 46507 | I38: 388577348 | J38: =I38/D38 -> 6996351.2 | K38: 102405000 | L38: =K38/I38 -> 0.26353826 | M38: 1 | N38: 18 | O38: 688000 | P38: Se envio recordatorio de pago
A39: KALA 4 | B39: 2A | C39: 53201 | D39: 111.21 | E39: 1429645320110 | F39: _x000D_1125797952 JHON DAIRO GALVIS RODRIGUEZ (100.00%) | G39: 45819 | H39: 46538 | I39: 1043293026 | J39: =I39/D39 -> 9381287.9 | K39: 277229728 | L39: =K39/I39 -> 0.26572566 | M39: 1 | N39: 18 | O39: 3250000 | P39: Compromiso de pago 15 de Julio 2026.
J40: =I40/D40 -> #DIV/0! | L40: =K40/I40 -> #DIV/0!
C41: =+COUNTA(C14:C40) -> 20 | F41: TOTALES | I41: =I13+I18+I26+I36 -> 13620730468 | K41: =K13+K18+K26+K36 -> 3286883268 | O41: =O13+O18+O26+O36 -> 152446127
A45: CARTERA EN TRAMITE
A46: INVENTARIO | B46: INMUEBLE | C46: NOMENCLATURA | D46: AREA | E46: REFERENCIA | F46: PROPIETARIOS | G46: FECHA CONTRATO | H46: FECHA DE ENTREGA | I46: VALOR VENTA | J46: VALOR M2 | K46: VALOR ABONADO | L46: % RECAUDO | M46: CUOTAS MORA | N46: DIAS MORA | O46: VALOR VENCIDO | P46: OBSERVACIONES
F47: Cartera Mayor de 90 dias | I47: =I48 -> 829283543 | K47: =K48 -> 42456000 | O47: =O48 -> 9550000
A48: KALA 4 | B48: 1-H | C48: 53109 | D48: 88.73 | E48: 1429645310917 | F48: _x000D_79404230 JUSTO ENRIQUE MORALES VANEGAS (100.00%) | G48: 45817 | H48: 46502 | I48: 829283543 | J48: =I48/D48 -> 9346146.1 | K48: 42456000 | L48: =K48/I48 -> 0.051196 | M48: 5 | N48: 136 | O48: 9550000 | P48: Desistimiento Radicado en sala de venta en proceso | Q48: PENALIDAD 50% DE LO PAGADO
...

Sheet RESUMEN 
B5: RESUMEN CARTERA FIDUCIARIA BANCOLOMBIA
C7: Etapa 3 | D7: Etapa 3 | E7: Etapa 3 | F7: Etapa 3 | G7: Etapa 4 | H7: Etapa 4 | I7: Etapa 4 | K7: Generado: 18-06-2026
C8: KALIZA TORRE 1 | D8: KALIZA TORRE 2 | E8: KALA 1 | F8: KALA 2 | G8: KALIZA TORRE 3 | H8: KALA 3 | I8: KALA 4 | J8: TOTAL | K8: Sin conciliar | L8: Total + Sin Conciliar
B9: Numero de Clientes Vinculados | C9: ='KALIZA T1'!F46 -> 84 | D9: ='KALIZA T2'!F54 -> 85 | E9: ='KALA T1'!G50 -> 60 | F9: ='KALA T2 '!E48 -> 67 | G9: ='KALIZA T3'!G61 -> 79 | H9: ='KALA T3'!E52 -> 57 | I9: ='KALA T4'!G65 -> 68 | J9: =SUM(C9:I9) -> 500
B10: Inventario | C10: ='KALIZA T1'!F45 -> 1 | D10: ='KALIZA T2'!F53 -> 0 | E10: ='KALA T1'!G49 -> 8 | F10: ='KALA T2 '!E47 -> 5 | G10: ='KALIZA T3'!G60 -> 6 | H10: ='KALA T3'!E51 -> 9 | I10: ='KALA T4'!G64 -> 12 | J10: =C10+D10+E10+F10+H10+I10 -> 35
B11: Valor Venta Clientes Vinculados | C11: 40051042530 | D11: 41088247196 | E11: 42307251147 | F11: 43764351773 | G11: 40571250678 | H11: 37160663439 | I11: 41308932948 | J11: =SUM(C11:I11) -> 286251739711
B12: Valor recaudado a la fecha | C12: ='KALIZA T1'!F49 -> 1.5162372e+10 | D12: ='KALIZA T2'!F57 -> 1.613708e+10 | E12: ='KALA T1'!G53 -> 1.5526661e+10 | F12: ='KALA T2 '!E51 -> 1.4460888e+10 | G12: ='KALIZA T3'!G62 -> 1.0461814e+10 | H12: ='KALA T3'!E55 -> 1.1465136e+10 | I12: ='KALA T4'!G66 -> 1.1927031e+10 | J12: =SUM(C12:I12) -> 9.5140982e+10 | K12: =C47+C65 -> 440368397 | L12: =J12+K12 -> 9.5581351e+10
B13: SALDO POR RECAUDAR CUOTA INICIAL | C13: 90749025 | D13: 84718105 | E13: 1.9609079e+09 | F13: 1.7181437e+09 | G13: 1.6359843e+09 | H13: 1.0015177e+08 | I13: 1.3554598e+09 | J13: =SUM(C13:I13) -> 6.9461146e+09 | K13: 277091581 | L13: Esto se encuentra en partidas sin conciliar de la etapa 3, pendiente por vincular 2 Clientes
B14: Porcentaje de Reacudo sobre la venta | C14: =C12/C11 -> 0.37857622 | D14: =D12/D11 -> 0.39274199 | E14: =E12/E11 -> 0.36699764 | F14: =F12/F11 -> 0.3304262 | G14: =G12/G11 -> 0.25786274 | H14: =H12/H11 -> 0.30852883 | I14: =I12/I11 -> 0.28872764 | J14: =J12/J11 -> 0.33236822
B15: Porcentaje de recaudo sobre la cuota inicial | C15: =[7]RESUMEN!$C$10 -> 0.99178962 | D15: 0.9948 | E15: 0.88786847 | F15: =[8]RESUMEN!$C$10 -> 0.88987039 | G15: 0.86477007 | H15: 0.99159971 | I15: 0.89795138
B16: RECAUDO (REAL+CARTERA VENCIDA) | C16: ='KALIZA T1'!F50 -> 1.5193476e+10 | D16: ='KALIZA T2'!F58 -> 1.6169954e+10 | E16: ='KALA T1'!G54 -> 1.5583432e+10 | F16: ='KALA T2 '!E52 -> 1.4597284e+10 | G16: ='KALIZA T3'!G65 -> 1.0529417e+10 | H16: ='KALA T3'!E56 -> 1.1584821e+10 | I16: ='KALA T4'!G69 -> 1.1946374e+10 | J16: =SUM(C16:I16) -> 9.5604757e+10
B17: Cartera > 5 dias | C17: ='KALIZA T1'!F51 -> 31103533 | D17: ='KALIZA T2'!F59 -> 32874078 | E17: ='KALA T1'!G55 -> 56770454 | F17: ='KALA T2 '!E53 -> 136395217 | G17: ='KALIZA T3'!G66 -> 48229029 | H17: ='KALA T3'!E57 -> 119684940 | I17: ='KALA T4'!G70 -> 161996127 | J17: =SUM(C17:I17) -> 587053378
B18: % de Cartera > 5 dias | C18: ='KALIZA T1'!F52 -> 0.0020471638 | D18: ='KALIZA T2'!F60 -> 0.0020330347 | E18: ='KALA T1'!G56 -> 0.0036430008 | F18: ='KALA T2 '!E54 -> 0.0093438766 | G18: ='KALIZA T3'!G67 -> 0.0045804085 | H18: ='KALA T3'!E58 -> 0.010331186 | I18: ='KALA T4'!G71 -> 0.013560276 | J18: =J17/J16 -> 0.0061404202
B19: Cartera < 5 dias | C19: ='KALIZA T1'!F53 -> 0 | D19: ='KALIZA T2'!F61 -> 3328800 | E19: ='KALA T1'!G57 -> 0 | F19: ='KALA T2 '!E55 -> 17592844 | G19: ='KALIZA T3'!G68 -> 19373828 | H19: ='KALA T3'!E59 -> 16593000 | I19: ='KALA T4'!G72 -> 7186000 | J19: =SUM(C19:I19) -> 64074472
B20: % Cartera < 5 dias | C20: ='KALIZA T1'!H60 -> 0 | D20: ='KALIZA T2'!F62 -> 0.00020586329 | E20: ='KALA T1'!G58 -> 0 | F20: ='KALA T2 '!E56 -> 0.0012052135 | G20: ='KALIZA T3'!G69 -> 0.0018399716 | H20: ='KALA T3'!E60 -> 0.0014323053 | I20: ='KALA T4'!G73 -> 0.00060152142 | J20: =J19/J16 -> 0.00067020171
B21: Cartera en tramite | C21: ='KALIZA T1'!F55 -> 2081700 | D21: ='KALIZA T2'!F63 -> 0 | E21: ='KALA T1'!G59 -> 13533830 | F21: ='KALA T2 '!E57 -> 33532431 | G21: ='KALIZA T3'!G70 -> 976000 | H21: ='KALA T3'!E61 -> 0 | I21: ='KALA T4'!G74 -> 9550000 | J21: =SUM(C21:I21) -> 59673961
B22: Cartera - Cartera Tramite | C22: ='KALIZA T1'!F56 -> 29021833 | D22: ='KALIZA T2'!G69 -> 0 | E22: ='KALA T1'!G60 -> 43236624 | F22: ='KALA T2 '!E58 -> 102862786 | G22: ='KALIZA T3'!G71 -> 47253029 | H22: ='KALA T3'!E62 -> 119684940 | I22: ='KALA T4'!G75 -> 152446127 | J22: =SUM(C22:I22) -> 494505339
B23: Desistimientos | C23: ='KALIZA T1'!F63 -> 0 | D23: ='KALIZA T2'!F69 -> 0 | E23: ='KALA T1'!G65 -> 0 | F23: ='KALA T2 '!E63 -> 0 | G23: ='KALIZA T3'!J76 -> 0 | H23: ='KALA T3'!E67 -> 0 | I23: ='KALA T4'!G80 -> 9550000 | J23: =SUM(C23:I23) -> 9550000
B24: # clientes desistimiento | C24: 0 | D24: 0 | E24: 0 | F24: 0 | G24: 0 | H24: 0 | I24: 1 | J24: =SUM(C24:I24) -> 1
B25: Otrosi | C25: ='KALIZA T1'!F62 -> 1637400 | D25: ='KALIZA T2'!F70 -> 0 | E25: ='KALA T1'!G66 -> 2744162 | F25: ='KALA T2 '!E64 -> 33532431 | G25: ='KALIZA T3'!G77 -> 0 | H25: ='[9]Cartera Kala T3'!G45 -> 0 | I25: ='[9]Cartera Kala 4'!H46 -> 0 | J25: =SUM(C25:I25) -> 37913993
B26: Monetizacion | C26: ='KALIZA T1'!F65 -> 0 | D26: ='[9]Cartera Kaliza T2'!G46 -> 0 | E26: ='[9]Cartera Kala T1'!I42 -> 0 | F26: ='KALA T2 '!E66 -> 0 | G26: ='KALIZA T3'!G78 -> 0 | H26: ='[9]Cartera Kala T3'!G46 -> 0 | I26: ='KALA T4'!G82 -> 0 | J26: =SUM(C26:I26) -> 0
B27: Partidas por conciliar | C27: ='[9]Cartera Kaliza 1 '!H42 -> 0 | D27: ='[9]Cartera Kaliza T2'!G47 -> 0 | E27: ='[9]Cartera Kala T1'!I43 -> 0 | F27: ='KALA T2 '!E67 -> 0 | G27: ='KALIZA T3'!G79 -> 0 | H27: ='[9]Cartera Kala T3'!G47 -> 0 | I27: ='KALA T4'!G83 -> 0 | J27: =SUM(C27:I27) -> 0
